During handling of the above exception, another exception occurred:

Traceback (most recent call last):
  File "/home/runner/WebScrapeNavigator/.pythonlibs/lib/python3.11/site-packages/kombu/connection.py", line 472, in _reraise_as_library_errors
    yield
  File "/home/runner/WebScrapeNavigator/.pythonlibs/lib/python3.11/site-packages/celery/app/base.py", line 787, in send_task
    self.backend.on_task_call(P, task_id)
  File "/home/runner/WebScrapeNavigator/.pythonlibs/lib/python3.11/site-packages/celery/backends/redis.py", line 365, in on_task_call
    self.result_consumer.consume_from(task_id)
  File "/home/runner/WebScrapeNavigator/.pythonlibs/lib/python3.11/site-packages/celery/backends/redis.py", line 161, in consume_from
    return self.start(task_id)
           ^^^^^^^^^^^^^^^^^^^
  File "/home/runner/WebScrapeNavigator/.pythonlibs/lib/python3.11/site-packages/celery/backends/redis.py", line 139, in start
    self._consume_from(initial_task_id)
  File "/home/runner/WebScrapeNavigator/.pythonlibs/lib/python3.11/site-packages/celery/backends/redis.py", line 168, in _consume_from
    with self.reconnect_on_error():
  File "/nix/store/f98g7xbckgqbkagdvpzc2r6lv3h1p9ki-python3-3.11.9/lib/python3.11/contextlib.py", line 158, in __exit__
    self.gen.throw(typ, value, traceback)
  File "/home/runner/WebScrapeNavigator/.pythonlibs/lib/python3.11/site-packages/celery/backends/redis.py", line 122, in reconnect_on_error
    self._ensure(self._reconnect_pubsub, ())
  File "/home/runner/WebScrapeNavigator/.pythonlibs/lib/python3.11/site-packages/celery/backends/redis.py", line 376, in ensure
    return retry_over_time(
           ^^^^^^^^^^^^^^^^
  File "/home/runner/WebScrapeNavigator/.pythonlibs/lib/python3.11/site-packages/kombu/utils/functional.py", line 318, in retry_over_time
    return fun(*args, **kwargs)
           ^^^^^^^^^^^^^^^^^^^^
  File "/home/runner/WebScrapeNavigator/.pythonlibs/lib/python3.11/site-packages/celery/backends/redis.py", line 106, in _reconnect_pubsub
    metas = self.backend.client.mget(self.subscribed_to)
            ^^^^^^^^^^^^^^^^^^^^^^^^^^^^^^^^^^^^^^^^^^^^
  File "/home/runner/WebScrapeNavigator/.pythonlibs/lib/python3.11/site-packages/redis/commands/core.py", line 2007, in mget
    return self.execute_command("MGET", *args, **options)
           ^^^^^^^^^^^^^^^^^^^^^^^^^^^^^^^^^^^^^^^^^^^^^^
  File "/home/runner/WebScrapeNavigator/.pythonlibs/lib/python3.11/site-packages/redis/client.py", line 545, in execute_command
    conn = self.connection or pool.get_connection(command_name, **options)
                              ^^^^^^^^^^^^^^^^^^^^^^^^^^^^^^^^^^^^^^^^^^^^
  File "/home/runner/WebScrapeNavigator/.pythonlibs/lib/python3.11/site-packages/redis/connection.py", line 1074, in get_connection
    connection.connect()
  File "/home/runner/WebScrapeNavigator/.pythonlibs/lib/python3.11/site-packages/redis/connection.py", line 283, in connect
    raise ConnectionError(self._error_message(e))
redis.exceptions.ConnectionError: Error 99 connecting to localhost:6379. Cannot assign requested address.

The above exception was the direct cause of the following exception:

Traceback (most recent call last):
  File "/home/runner/WebScrapeNavigator/.pythonlibs/lib/python3.11/site-packages/flask/app.py", line 1473, in wsgi_app
    response = self.full_dispatch_request()
               ^^^^^^^^^^^^^^^^^^^^^^^^^^^^
  File "/home/runner/WebScrapeNavigator/.pythonlibs/lib/python3.11/site-packages/flask/app.py", line 882, in full_dispatch_request
    rv = self.handle_user_exception(e)
         ^^^^^^^^^^^^^^^^^^^^^^^^^^^^^
  File "/home/runner/WebScrapeNavigator/.pythonlibs/lib/python3.11/site-packages/flask/app.py", line 880, in full_dispatch_request
    rv = self.dispatch_request()
         ^^^^^^^^^^^^^^^^^^^^^^^
  File "/home/runner/WebScrapeNavigator/.pythonlibs/lib/python3.11/site-packages/flask/app.py", line 865, in dispatch_request
    return self.ensure_sync(self.view_functions[rule.endpoint])(**view_args)  # type: ignore[no-any-return]
           ^^^^^^^^^^^^^^^^^^^^^^^^^^^^^^^^^^^^^^^^^^^^^^^^^^^^^^^^^^^^^^^^^
  File "/home/runner/WebScrapeNavigator/main.py", line 26, in scrape
    task = scrape_website.delay(url, max_pages=200, ignore_robots=True, max_workers=max_workers, auth=auth, preprocessing_options=preprocessing_options)
           ^^^^^^^^^^^^^^^^^^^^^^^^^^^^^^^^^^^^^^^^^^^^^^^^^^^^^^^^^^^^^^^^^^^^^^^^^^^^^^^^^^^^^^^^^^^^^^^^^^^^^^^^^^^^^^^^^^^^^^^^^^^^^^^^^^^^^^^^^^^^^
  File "/home/runner/WebScrapeNavigator/.pythonlibs/lib/python3.11/site-packages/celery/app/task.py", line 425, in delay
    return self.apply_async(args, kwargs)
           ^^^^^^^^^^^^^^^^^^^^^^^^^^^^^^
  File "/home/runner/WebScrapeNavigator/.pythonlibs/lib/python3.11/site-packages/celery/app/task.py", line 575, in apply_async
    return app.send_task(
           ^^^^^^^^^^^^^^
  File "/home/runner/WebScrapeNavigator/.pythonlibs/lib/python3.11/site-packages/celery/app/base.py", line 785, in send_task
    with P.connection._reraise_as_library_errors():
  File "/nix/store/f98g7xbckgqbkagdvpzc2r6lv3h1p9ki-python3-3.11.9/lib/python3.11/contextlib.py", line 158, in __exit__
    self.gen.throw(typ, value, traceback)
  File "/home/runner/WebScrapeNavigator/.pythonlibs/lib/python3.11/site-packages/kombu/connection.py", line 476, in _reraise_as_library_errors
    raise ConnectionError(str(exc)) from exc
kombu.exceptions.OperationalError: Error 99 connecting to localhost:6379. Cannot assign requested address.