The above exception was the direct cause of the following exception:

Traceback (most recent call last):
  File "/home/runner/WebScrapeNavigator/.pythonlibs/lib/python3.11/site-packages/flask/app.py", line 1473, in wsgi_app
    response = self.full_dispatch_request()
               ^^^^^^^^^^^^^^^^^^^^^^^^^^^^
  File "/home/runner/WebScrapeNavigator/.pythonlibs/lib/python3.11/site-packages/flask/app.py", line 882, in full_dispatch_request
    rv = self.handle_user_exception(e)
         ^^^^^^^^^^^^^^^^^^^^^^^^^^^^^
  File "/home/runner/WebScrapeNavigator/.pythonlibs/lib/python3.11/site-packages/flask/app.py", line 880, in full_dispatch_request
    rv = self.dispatch_request()
         ^^^^^^^^^^^^^^^^^^^^^^^
  File "/home/runner/WebScrapeNavigator/.pythonlibs/lib/python3.11/site-packages/flask/app.py", line 865, in dispatch_request
    return self.ensure_sync(self.view_functions[rule.endpoint])(**view_args)  # type: ignore[no-any-return]
           ^^^^^^^^^^^^^^^^^^^^^^^^^^^^^^^^^^^^^^^^^^^^^^^^^^^^^^^^^^^^^^^^^
  File "/home/runner/WebScrapeNavigator/main.py", line 26, in scrape
    task = scrape_website.delay(url, max_pages=200, ignore_robots=True, max_workers=max_workers, auth=auth, preprocessing_options=preprocessing_options)
           ^^^^^^^^^^^^^^^^^^^^^^^^^^^^^^^^^^^^^^^^^^^^^^^^^^^^^^^^^^^^^^^^^^^^^^^^^^^^^^^^^^^^^^^^^^^^^^^^^^^^^^^^^^^^^^^^^^^^^^^^^^^^^^^^^^^^^^^^^^^^^
  File "/home/runner/WebScrapeNavigator/.pythonlibs/lib/python3.11/site-packages/celery/app/task.py", line 425, in delay
    return self.apply_async(args, kwargs)
           ^^^^^^^^^^^^^^^^^^^^^^^^^^^^^^
  File "/home/runner/WebScrapeNavigator/.pythonlibs/lib/python3.11/site-packages/celery/app/task.py", line 575, in apply_async
    return app.send_task(
           ^^^^^^^^^^^^^^
  File "/home/runner/WebScrapeNavigator/.pythonlibs/lib/python3.11/site-packages/celery/app/base.py", line 785, in send_task
    with P.connection._reraise_as_library_errors():
  File "/nix/store/f98g7xbckgqbkagdvpzc2r6lv3h1p9ki-python3-3.11.9/lib/python3.11/contextlib.py", line 158, in __exit__
    self.gen.throw(typ, value, traceback)
  File "/home/runner/WebScrapeNavigator/.pythonlibs/lib/python3.11/site-packages/kombu/connection.py", line 476, in _reraise_as_library_errors
    raise ConnectionError(str(exc)) from exc
kombu.exceptions.OperationalError: Error 99 connecting to localhost:6379. Cannot assign requested address.
172.31.196.114 - - [18/Sep/2024 06:25:53] "POST /scrape HTTP/1.1" 500 -